Workbook

Sheet Tax 25-26
A1: S. no | B1: Region | C1: Employee ID | D1: Name | E1: Designation | F1: Department | G1: Net Salary | H1: Increment | I1: Incremental Arrears | J1: appraisal amount (1) | K1: appraisal amount (2) | L1: SUM of Year Salary | M1: Incentive (July) | N1: Incentive (August) | O1: Incentive (Sep) | P1: Incentive (Oct) | Q1: Incentive (Nov) | R1: Incentive (Dec) | S1: Incentive (Jan) | T1: Incentive (Feb) | U1: Incentive (Mar) | V1: Incentive (Apr) | W1: Incentive (May) | X1: Incentive (Jun) | Y1: Com (July) | Z1: Com (August) | AA1: Com (Sep) | AB1: Com (Oct) | AC1: Com (Nov) | AD1: Com (Dec) | AE1: Com (Jan) | AF1: Com (Feb) | AG1: Com (Mar) | AH1: Com (Apr) | AI1: Com (May) | AJ1: Com (Jun) | AK1: TOTAL SALARY + TOTAL COM & INCEN. | AL1: TOTAL SALARY + TOTAL COM & INCEN/12 | AM1: Yearly Tax | AN1: AlreadyTax Paid | AO1: Remaining Tax | AP1: Pending Month | AQ1: Current Tax for deduction | AR1: Remarks
F2: 1200000 to 2200000 | G2: 0.11
F3: 2200000 to 3200000 | G3: 0.23
F4: 3200000 to 4100000 | G4: 0.3 | K4: =1138505+2136740 -> 3275245
F5: More than 4100000 | G5: 0.35
AQ6: Deduction in payroll
A7: S. no | B7: Region | C7: Employee ID | D7: Name | E7: Designation | F7: Department | G7: Net Salary | H7: Increments | I7: Incremental Arrears | J7: appraisal amount (1) | K7: appraisal amount (2) | L7: SUM of Year Salary | M7: Incentive (July) | N7: Incentive (August) | O7: Incentive (Sep) | P7: Incentive (Oct) | Q7: Incentive (Nov) | R7: Incentive (Dec) | S7: Incentive (Jan) | T7: Incentive (Feb) | U7: Incentive (Mar) | V7: Incentive (Apr) | W7: Incentive (May) | X7: Incentive (Jun) | Y7: Com (July) | Z7: Com (August) | AA7: Com (Sep) | AB7: Com (Oct) | AC7: Com (Nov) | AD7: Com (Dec) | AE7: Com (Jan) | AF7: Com (Feb) | AG7: Com (Mar) | AH7: Com (Apr) | AI7: Com (May) | AJ7: Com (Jun) | AK7: TOTAL SALARY + TOTAL COM & INCEN. | AL7: TOTAL SALARY + TOTAL COM & INCEN/12 | AM7: Yearly Tax | AN7: AlreadyTax Paid | AO7: Remaining Tax | AP7: Pending Month | AQ7: Current Tax for deduction | AR7: Remarks | AS7: Put this amount in payroll
A8: 1 | B8: Karachi | C8: 10001 | D8: Syed Salman Hussain | E8: CEO | F8: Management | G8: 3275245 | J8: 0 | K8: 0 | L8: =G8*12+H8+J8+K8+I8 -> 39302940 | M8: 0 | N8: 0 | O8: 0 | P8: 0 | Q8: =VLOOKUP(C8,Incentives!C2:K340,9,FALSE) -> 0 | R8: 0 | S8: 0 | T8: 0 | Y8: 0 | Z8: 0 | AA8: 0 | AB8: 0 | AC8: 0 | AD8: 0 | AE8: 0 | AF8: 0 | AK8: =SUM(L8:AJ8) -> 39302940 | AL8: =AK8/12 -> 3275245 | AM8: =IF(AK8<=600000,0, IF(AK8<=1200000,(AK8-600000)*0.01, IF(AK8<=2200000,(AK8-1200000)*0.11+6000, IF(AK8<=3200000,(AK8-2200000)*0.23+116000, IF(AK8<=4100000,(AK8-3200000)*0.3+346000, (AK8-4100000)*0.35+616000))))) *(1+IF(AK8>10000000,9%,0)) -> 14101362 | AN8: =VLOOKUP(C8,'Paid Tax'!B3:M364,12,FALSE) -> 8225794.2 | AO8: =+AM8-AN8 -> 5875567.4 | AP8: 5 | AQ8: =+AO8/AP8 -> 1175113.5 | AS8: =-AQ8 -> -1175113.5
A9: 2 | B9: Karachi | C9: 20001 | D9: Ahmed Farid Bokhari | E9: Director | F9: Management | G9: 408946 | J9: 0 | K9: 0 | L9: =G9*12+H9+J9+K9+I9 -> 4907352 | M9: 0 | N9: 0 | O9: 0 | P9: 0 | Q9: =VLOOKUP(C9,Incentives!C3:K341,9,FALSE) -> 0 | R9: 0 | S9: 0 | T9: 0 | Y9: 0 | Z9: 0 | AA9: 0 | AB9: 0 | AC9: 0 | AD9: 0 | AE9: 0 | AF9: 0 | AK9: =SUM(L9:AJ9) -> 4907352 | AL9: =AK9/12 -> 408946 | AM9: =IF(AK9<=600000,0, IF(AK9<=1200000,(AK9-600000)*0.01, IF(AK9<=2200000,(AK9-1200000)*0.11+6000, IF(AK9<=3200000,(AK9-2200000)*0.23+116000, IF(AK9<=4100000,(AK9-3200000)*0.3+346000, (AK9-4100000)*0.35+616000))))) *(1+IF(AK9>10000000,9%,0)) -> 898573.2 | AN9: =VLOOKUP(C9,'Paid Tax'!B4:M365,12,FALSE) -> 524167.7 | AO9: =+AM9-AN9 -> 374405.5 | AP9: 5 | AQ9: =+AO9/AP9 -> 74881.1 | AS9: =-AQ9 -> -74881.1 | AT9: =81881.1*8 -> 655048.8
A10: 3 | B10: Karachi | C10: 10520 | D10: Nadeem Qasim | E10: Personal Assistant | F10: Management | G10: 85000 | J10: 0 | K10: 0 | L10: =G10*12+H10+J10+K10+I10 -> 1020000 | M10: 0 | N10: 0 | O10: 0 | P10: 0 | Q10: =VLOOKUP(C10,Incentives!C4:K342,9,FALSE) -> 0 | R10: 0 | S10: 0 | T10: 0 | Y10: 0 | Z10: 0 | AA10: 0 | AB10: 0 | AC10: 0 | AD10: 0 | AE10: 0 | AF10: 0 | AK10: =SUM(L10:AJ10) -> 1020000 | AL10: =AK10/12 -> 85000 | AM10: =IF(AK10<=600000,0, IF(AK10<=1200000,(AK10-600000)*0.01, IF(AK10<=2200000,(AK10-1200000)*0.11+6000, IF(AK10<=3200000,(AK10-2200000)*0.23+116000, IF(AK10<=4100000,(AK10-3200000)*0.3+346000, (AK10-4100000)*0.35+616000))))) *(1+IF(AK10>10000000,9%,0)) -> 4200 | AN10: =VLOOKUP(C10,'Paid Tax'!B5:M366,12,FALSE) -> 2450 | AO10: =+AM10-AN10 -> 1750 | AP10: 5 | AQ10: =+AO10/AP10 -> 350 | AS10: =-AQ10 -> -350
A11: 4 | B11: Karachi | C11: 10002 | D11: Ubaid Ullah | E11: Head, Admin | F11: Admin | G11: 144364 | J11: 13878.75 | K11: 13878.75 | L11: =G11*12+H11+J11+K11+I11 -> 1760125.5 | M11: 0 | N11: 0 | O11: 0 | P11: 0 | Q11: =VLOOKUP(C11,Incentives!C5:K343,9,FALSE) -> 0 | R11: 0 | S11: 0 | T11: 0 | Y11: 0 | Z11: 0 | AA11: 0 | AB11: 0 | AC11: 0 | AD11: 0 | AE11: 0 | AF11: 0 | AK11: =SUM(L11:AJ11) -> 1760125.5 | AL11: =AK11/12 -> 146677.12 | AM11: =IF(AK11<=600000,0, IF(AK11<=1200000,(AK11-600000)*0.01, IF(AK11<=2200000,(AK11-1200000)*0.11+6000, IF(AK11<=3200000,(AK11-2200000)*0.23+116000, IF(AK11<=4100000,(AK11-3200000)*0.3+346000, (AK11-4100000)*0.35+616000))))) *(1+IF(AK11>10000000,9%,0)) -> 67613.805 | AN11: =VLOOKUP(C11,'Paid Tax'!B6:M367,12,FALSE) -> 39383.558 | AO11: =+AM11-AN11 -> 28230.247 | AP11: 5 | AQ11: =+AO11/AP11 -> 5646.0494 | AS11: =-AQ11 -> -5646.0494
A12: 5 | B12: Karachi | C12: 10003 | D12: Furqan | E12: Supervisor, Admin | F12: Admin | G12: 80177 | J12: 8000 | K12: 8000 | L12: =G12*12+H12+J12+K12+I12 -> 978124 | M12: 0 | N12: 0 | O12: 0 | P12: 0 | Q12: =VLOOKUP(C12,Incentives!C6:K344,9,FALSE) -> 0 | R12: 0 | S12: 0 | T12: 0 | Y12: 0 | Z12: 0 | AA12: 0 | AB12: 0 | AC12: 0 | AD12: 0 | AE12: 0 | AF12: 0 | AK12: =SUM(L12:AJ12) -> 978124 | AL12: =AK12/12 -> 81510.333 | AM12: =IF(AK12<=600000,0, IF(AK12<=1200000,(AK12-600000)*0.01, IF(AK12<=2200000,(AK12-1200000)*0.11+6000, IF(AK12<=3200000,(AK12-2200000)*0.23+116000, IF(AK12<=4100000,(AK12-3200000)*0.3+346000, (AK12-4100000)*0.35+616000))))) *(1+IF(AK12>10000000,9%,0)) -> 3781.24 | AN12: =VLOOKUP(C12,'Paid Tax'!B7:M368,12,FALSE) -> 2202.693 | AO12: =+AM12-AN12 -> 1578.547 | AP12: 5 | AQ12: =+AO12/AP12 -> 315.70939 | AS12: =-AQ12 -> -315.70939
A13: 6 | B13: Karachi | C13: 10418 | D13: Syed Omar Farooq Naqvi | E13: Officer, Admin | F13: Admin | G13: 45000 | J13: 5000 | K13: 5000 | L13: =G13*12+H13+J13+K13+I13 -> 550000 | M13: 0 | N13: 0 | O13: 0 | P13: 0 | Q13: =VLOOKUP(C13,Incentives!C7:K345,9,FALSE) -> 0 | R13: 0 | S13: 0 | T13: 0 | Y13: 0 | Z13: 0 | AA13: 0 | AB13: 0 | AC13: 0 | AD13: 0 | AE13: 0 | AF13: 0 | AK13: =SUM(L13:AJ13) -> 550000 | AL13: =AK13/12 -> 45833.333 | AM13: =IF(AK13<=600000,0, IF(AK13<=1200000,(AK13-600000)*0.01, IF(AK13<=2200000,(AK13-1200000)*0.11+6000, IF(AK13<=3200000,(AK13-2200000)*0.23+116000, IF(AK13<=4100000,(AK13-3200000)*0.3+346000, (AK13-4100000)*0.35+616000))))) *(1+IF(AK13>10000000,9%,0)) -> 0 | AN13: =VLOOKUP(C13,'Paid Tax'!B8:M369,12,FALSE) -> 0 | AO13: =+AM13-AN13 -> 0 | AP13: 5 | AQ13: =+AO13/AP13 -> 0 | AS13: =-AQ13 -> 0 | AW13: Aug
A14: 7 | B14: Karachi | C14: 10006 | D14: Humna Altamash Yousuf | E14: Head - HR & Cultural Development | F14: Human Resources | G14: 142552 | J14: 20000 | K14: 20000 | L14: =G14*12+H14+J14+K14+I14 -> 1750624 | M14: 0 | N14: 0 | O14: 0 | P14: 0 | Q14: =VLOOKUP(C14,Incentives!C8:K346,9,FALSE) -> 0 | R14: 0 | S14: 0 | T14: 0 | Y14: 0 | Z14: 0 | AA14: 0 | AB14: 0 | AC14: 0 | AD14: 0 | AE14: 0 | AF14: 0 | AK14: =SUM(L14:AJ14) -> 1750624 | AL14: =AK14/12 -> 145885.33 | AM14: =IF(AK14<=600000,0, IF(AK14<=1200000,(AK14-600000)*0.01, IF(AK14<=2200000,(AK14-1200000)*0.11+6000, IF(AK14<=3200000,(AK14-2200000)*0.23+116000, IF(AK14<=4100000,(AK14-3200000)*0.3+346000, (AK14-4100000)*0.35+616000))))) *(1+IF(AK14>10000000,9%,0)) -> 66568.64 | AN14: =VLOOKUP(C14,'Paid Tax'!B9:M370,12,FALSE) -> 38748.373 | AO14: =+AM14-AN14 -> 27820.267 | AP14: 5 | AQ14: =+AO14/AP14 -> 5564.0533 | AS14: =-AQ14 -> -5564.0533 | AW14: Sep
A15: 8 | B15: Karachi | C15: 10008 | D15: Muhammad Fahad | E15: Head - Financial Governance & Compliance | F15: Accounts & Finance | G15: 300276 | J15: 60000 | K15: 60000 | L15: =G15*12+H15+J15+K15+I15 -> 3723312 | M15: 0 | N15: 0 | O15: 0 | P15: 0 | Q15: =VLOOKUP(C15,Incentives!C9:K347,9,FALSE) -> 0 | R15: 0 | S15: 0 | T15: 0 | Y15: 0 | Z15: 0 | AA15: 0 | AB15: 0 | AC15: 0 | AD15: 0 | AE15: 0 | AF15: 0 | AK15: =SUM(L15:AJ15) -> 3723312 | AL15: =AK15/12 -> 310276 | AM15: =IF(AK15<=600000,0, IF(AK15<=1200000,(AK15-600000)*0.01, IF(AK15<=2200000,(AK15-1200000)*0.11+6000, IF(AK15<=3200000,(AK15-2200000)*0.23+116000, IF(AK15<=4100000,(AK15-3200000)*0.3+346000, (AK15-4100000)*0.35+616000))))) *(1+IF(AK15>10000000,9%,0)) -> 502993.6 | AN15: =VLOOKUP(C15,'Paid Tax'!B10:M371,12,FALSE) -> 292731.12 | AO15: =+AM15-AN15 -> 210262.48 | AP15: 5 | AQ15: =+AO15/AP15 -> 42052.497 | AS15: =-AQ15 -> -42052.497 | AW15: Oct
A16: 9 | B16: Karachi | C16: 10009 | D16: Muhammad Shaukat | E16: Supervisor, Recovery & Collection | F16: Accounts & Finance | G16: 57666 | J16: 9000 | K16: 9000 | L16: =G16*12+H16+J16+K16+I16 -> 709992 | M16: 0 | N16: 0 | O16: 0 | P16: 0 | Q16: =VLOOKUP(C16,Incentives!C10:K348,9,FALSE) -> 0 | R16: 0 | S16: 0 | T16: 0 | Y16: 0 | Z16: 0 | AA16: 0 | AB16: 0 | AC16: 0 | AD16: 0 | AE16: 0 | AF16: 0 | AK16: =SUM(L16:AJ16) -> 709992 | AL16: =AK16/12 -> 59166 | AM16: =IF(AK16<=600000,0, IF(AK16<=1200000,(AK16-600000)*0.01, IF(AK16<=2200000,(AK16-1200000)*0.11+6000, IF(AK16<=3200000,(AK16-2200000)*0.23+116000, IF(AK16<=4100000,(AK16-3200000)*0.3+346000, (AK16-4100000)*0.35+616000))))) *(1+IF(AK16>10000000,9%,0)) -> 1099.92 | AN16: =VLOOKUP(C16,'Paid Tax'!B11:M372,12,FALSE) -> 638.21091 | AO16: =+AM16-AN16 -> 461.70909 | AP16: 5 | AQ16: =+AO16/AP16 -> 92.341818 | AS16: =-AQ16 -> -92.341818 | AW16: Nov
A17: 10 | B17: Karachi | C17: 10010 | D17: Vivian Charles Paul | E17: Head - Corporate Services & Renewal | F17: Corporate Services | G17: 249654 | J17: 40000 | K17: 40000 | L17: =G17*12+H17+J17+K17+I17 -> 3075848 | M17: 0 | N17: 0 | O17: 0 | P17: 0 | Q17: =VLOOKUP(C17,Incentives!C11:K350,9,FALSE) -> 0 | R17: 0 | S17: 0 | T17: 0 | Y17: 19310 | Z17: 44796 | AA17: 21587 | AB17: 21284 | AC17: 25915 | AD17: 18486 | AE17: 25544 | AF17: 35743 | AK17: =SUM(L17:AJ17) -> 3288513 | AL17: =AK17/12 -> 274042.75 | AM17: =IF(AK17<=600000,0, IF(AK17<=1200000,(AK17-600000)*0.01, IF(AK17<=2200000,(AK17-1200000)*0.11+6000, IF(AK17<=3200000,(AK17-2200000)*0.23+116000, IF(AK17<=4100000,(AK17-3200000)*0.3+346000, (AK17-4100000)*0.35+616000))))) *(1+IF(AK17>10000000,9%,0)) -> 372553.9 | AN17: =VLOOKUP(C17,'Paid Tax'!B12:M373,12,FALSE) -> 203022.92 | AO17: =+AM17-AN17 -> 169530.98 | AP17: 5 | AQ17: =+AO17/AP17 -> 33906.196 | AS17: =-AQ17 -> -33906.196
A18: 11 | B18: Karachi | C18: 10011 | D18: Sidra | E18: Manager, CS | F18: Corporate Services | G18: 98221 | J18: 11000 | K18: 11000 | L18: =G18*12+H18+J18+K18+I18 -> 1200652 | M18: 0 | N18: 0 | O18: 0 | P18: 0 | Q18: =VLOOKUP(C18,Incentives!C12:K351,9,FALSE) -> 0 | R18: 0 | S18: 0 | T18: 0 | Y18: 0 | Z18: 0 | AA18: 0 | AB18: 0 | AC18: 0 | AD18: 0 | AE18: 0 | AF18: 0 | AK18: =SUM(L18:AJ18) -> 1200652 | AL18: =AK18/12 -> 100054.33 | AM18: =IF(AK18<=600000,0, IF(AK18<=1200000,(AK18-600000)*0.01, IF(AK18<=2200000,(AK18-1200000)*0.11+6000, IF(AK18<=3200000,(AK18-2200000)*0.23+116000, IF(AK18<=4100000,(AK18-3200000)*0.3+346000, (AK18-4100000)*0.35+616000))))) *(1+IF(AK18>10000000,9%,0)) -> 6071.72 | AN18: =VLOOKUP(C18,'Paid Tax'!B13:M374,12,FALSE) -> 3535.2003 | AO18: =+AM18-AN18 -> 2536.5197 | AP18: 5 | AQ18: =+AO18/AP18 -> 507.30394 | AS18: =-AQ18 -> -507.30394
A19: 12 | B19: Karachi | C19: 10494 | D19: Dawood | E19: Supervisor, CS | F19: Corporate Services | G19: 53650 | J19: 6650 | K19: 6650 | L19: =G19*12+H19+J19+K19+I19 -> 657100 | M19: 0 | N19: 0 | O19: 0 | P19: 0 | Q19: =VLOOKUP(C19,Incentives!C13:K352,9,FALSE) -> 0 | R19: 0 | S19: 0 | T19: 0 | Y19: 0 | Z19: 3000 | AA19: 4000 | AB19: 0 | AC19: 0 | AD19: 0 | AE19: 0 | AF19: 0 | AK19: =SUM(L19:AJ19) -> 664100 | AL19: =AK19/12 -> 55341.667 | AM19: =IF(AK19<=600000,0, IF(AK19<=1200000,(AK19-600000)*0.01, IF(AK19<=2200000,(AK19-1200000)*0.11+6000, IF(AK19<=3200000,(AK19-2200000)*0.23+116000, IF(AK19<=4100000,(AK19-3200000)*0.3+346000, (AK19-4100000)*0.35+616000))))) *(1+IF(AK19>10000000,9%,0)) -> 641 | AN19: =VLOOKUP(C19,'Paid Tax'!B14:M375,12,FALSE) -> 366.92803 | AO19: =+AM19-AN19 -> 274.07197 | AP19: 5 | AQ19: =+AO19/AP19 -> 54.814394 | AS19: =-AQ19 -> -54.814394
A20: 13 | B20: Karachi | C20: 10015 | D20: Syed Zia Abid Naqvi | E20: Head - Client Services | F20: Control Center | G20: 242087 | J20: 45000 | K20: 45000 | L20: =G20*12+H20+J20+K20+I20 -> 2995044 | M20: 0 | N20: 0 | O20: 0 | P20: 0 | Q20: =VLOOKUP(C20,Incentives!C14:K353,9,FALSE) -> 0 | R20: 0 | S20: 0 | T20: 0 | Y20: 118022 | Z20: 197878 | AA20: 138381 | AB20: 171051 | AC20: 202235 | AD20: 149431 | AE20: 150134 | AF20: 114069 | AK20: =SUM(L20:AJ20) -> 4236245 | AL20: =AK20/12 -> 353020.42 | AM20: =IF(AK20<=600000,0, IF(AK20<=1200000,(AK20-600000)*0.01, IF(AK20<=2200000,(AK20-1200000)*0.11+6000, IF(AK20<=3200000,(AK20-2200000)*0.23+116000, IF(AK20<=4100000,(AK20-3200000)*0.3+346000, (AK20-4100000)*0.35+616000))))) *(1+IF(AK20>10000000,9%,0)) -> 663685.75 | AN20: =VLOOKUP(C20,'Paid Tax'!B15:M376,12,FALSE) -> 305654.05 | AO20: =+AM20-AN20 -> 358031.7 | AP20: 5 | AQ20: =+AO20/AP20 -> 71606.34 | AS20: =-AQ20 -> -71606.34
A21: 14 | B21: Karachi | C21: 10016 | D21: Sobia Ali | E21: Head - Technical Operations & Diagnostics | F21: Diagnostics & Harness | G21: 175425 | J21: 30000 | K21: 30000 | L21: =G21*12+H21+J21+K21+I21 -> 2165100 | M21: 0 | N21: 0 | O21: 0 | P21: 0 | Q21: =VLOOKUP(C21,Incentives!C15:K354,9,FALSE) -> 0 | R21: 0 | S21: 0 | T21: 0 | Y21: 0 | Z21: 0 | AA21: 0 | AB21: 0 | AC21: 0 | AD21: 0 | AE21: 0 | AF21: 0 | AK21: =SUM(L21:AJ21) -> 2165100 | AL21: =AK21/12 -> 180425 | AM21: =IF(AK21<=600000,0, IF(AK21<=1200000,(AK21-600000)*0.01, IF(AK21<=2200000,(AK21-1200000)*0.11+6000, IF(AK21<=3200000,(AK21-2200000)*0.23+116000, IF(AK21<=4100000,(AK21-3200000)*0.3+346000, (AK21-4100000)*0.35+616000))))) *(1+IF(AK21>10000000,9%,0)) -> 112161 | AN21: =VLOOKUP(C21,'Paid Tax'!B16:M377,12,FALSE) -> 65302.25 | AO21: =+AM21-AN21 -> 46858.75 | AP21: 5 | AQ21: =+AO21/AP21 -> 9371.75 | AS21: =-AQ21 -> -9371.75
A22: 15 | B22: Karachi | C22: 10239 | D22: Syed Ayyan Ali | E22: CRO | F22: Control Center | G22: 35065 | J22: 4573.5 | K22: 4573.5 | L22: =G22*12+H22+J22+K22+I22 -> 429927 | M22: 0 | N22: 0 | O22: 0 | P22: 0 | Q22: =VLOOKUP(C22,Incentives!C16:K355,9,FALSE) -> 0 | R22: 0 | S22: 0 | T22: 0 | Y22: 2000 | Z22: 0 | AA22: 1000 | AB22: 5000 | AC22: 0 | AD22: 1000 | AE22: 0 | AF22: 0 | AK22: =SUM(L22:AJ22) -> 438927 | AL22: =AK22/12 -> 36577.25 | AM22: =IF(AK22<=600000,0, IF(AK22<=1200000,(AK22-600000)*0.01, IF(AK22<=2200000,(AK22-1200000)*0.11+6000, IF(AK22<=3200000,(AK22-2200000)*0.23+116000, IF(AK22<=4100000,(AK22-3200000)*0.3+346000, (AK22-4100000)*0.35+616000))))) *(1+IF(AK22>10000000,9%,0)) -> 0 | AN22: =VLOOKUP(C22,'Paid Tax'!B17:M378,12,FALSE) -> 0 | AO22: =+AM22-AN22 -> 0 | AP22: 5 | AQ22: =+AO22/AP22 -> 0 | AS22: =-AQ22 -> 0
A23: 16 | B23: Karachi | C23: 10018 | D23: Joseph Henry | E23: Deputy Manager, CR | F23: Control Center | G23: 52655 | J23: 7262.6 | K23: 7262.6 | L23: =G23*12+H23+J23+K23+I23 -> 646385.2 | M23: 0 | N23: 0 | O23: 0 | P23: 0 | Q23: =VLOOKUP(C23,Incentives!C17:K356,9,FALSE) -> 0 | R23: 0 | S23: 0 | T23: 0 | Y23: 61300 | Z23: 130390 | AA23: 41650 | AB23: 48050 | AC23: 81350 | AD23: 66130 | AE23: 73504 | AF23: 0 | AK23: =SUM(L23:AJ23) -> 1148759.2 | AL23: =AK23/12 -> 95729.933 | AM23: =IF(AK23<=600000,0, IF(AK23<=1200000,(AK23-600000)*0.01, IF(AK23<=2200000,(AK23-1200000)*0.11+6000, IF(AK23<=3200000,(AK23-2200000)*0.23+116000, IF(AK23<=4100000,(AK23-3200000)*0.3+346000, (AK23-4100000)*0.35+616000))))) *(1+IF(AK23>10000000,9%,0)) -> 5487.592 | AN23: =VLOOKUP(C23,'Paid Tax'!B18:M379,12,FALSE) -> 2375.4197 | AO23: =+AM23-AN23 -> 3112.1723 | AP23: 5 | AQ23: =+AO23/AP23 -> 622.43445 | AS23: =-AQ23 -> -622.43445
A24: 17 | B24: Karachi | C24: 10019 | D24: Anil | E24: Deputy Manager, CR | F24: Control Center | G24: 52758 | J24: 7277.05 | K24: 7277.05 | L24: =G24*12+H24+J24+K24+I24 -> 647650.1 | M24: 0 | N24: 0 | O24: 0 | P24: 0 | Q24: =VLOOKUP(C24,Incentives!C18:K357,9,FALSE) -> 0 | R24: 0 | S24: 0 | T24: 0 | Y24: 91891 | Z24: 180152 | AA24: 86376 | AB24: 90051 | AC24: 158710 | AD24: 103018 | AE24: 102636 | AF24: 1286 | AK24: =SUM(L24:AJ24) -> 1461770.1 | AL24: =AK24/12 -> 121814.18 | AM24: =IF(AK24<=600000,0, IF(AK24<=1200000,(AK24-600000)*0.01, IF(AK24<=2200000,(AK24-1200000)*0.11+6000, IF(AK24<=3200000,(AK24-2200000)*0.23+116000, IF(AK24<=4100000,(AK24-3200000)*0.3+346000, (AK24-4100000)*0.35+616000))))) *(1+IF(AK24>10000000,9%,0)) -> 34794.711 | AN24: =VLOOKUP(C24,'Paid Tax'!B19:M380,12,FALSE) -> 10396.326 | AO24: =+AM24-AN24 -> 24398.385 | AP24: 5 | AQ24: =+AO24/AP24 -> 4879.6769 | AS24: =-AQ24 -> -4879.6769
A25: 18 | B25: Karachi | C25: 10498 | D25: Moses Akhter | E25: Collection Officer | F25: Removal | G25: 35080 | J25: 3080 | K25: 3080 | L25: =G25*12+H25+J25+K25+I25 -> 427120 | M25: 0 | N25: 0 | O25: 0 | P25: 0 | Q25: =VLOOKUP(C25,Incentives!C19:K358,9,FALSE) -> 0 | R25: 0 | S25: 0 | T25: 0 | Y25: 23512 | Z25: 29223 | AA25: 23783 | AB25: 57050 | AC25: 27590 | AD25: 24885 | AE25: 25202 | AF25: 26049 | AK25: =SUM(L25:AJ25) -> 664414 | AL25: =AK25/12 -> 55367.833 | AM25: =IF(AK25<=600000,0, IF(AK25<=1200000,(AK25-600000)*0.01, IF(AK25<=2200000,(AK25-1200000)*0.11+6000, IF(AK25<=3200000,(AK25-2200000)*0.23+116000, IF(AK25<=4100000,(AK25-3200000)*0.3+346000, (AK25-4100000)*0.35+616000))))) *(1+IF(AK25>10000000,9%,0)) -> 644.14 | AN25: =VLOOKUP(C25,'Paid Tax'!B20:M381,12,FALSE) -> 42.025903 | AO25: =+AM25-AN25 -> 602.1141 | AP25: 11 | AQ25: =+AO25/AP25 -> 54.737645 | AR25: First time tax will be / by 11 | AS25: =-AQ25 -> -54.737645
A26: 19 | B26: Karachi | C26: 10020 | D26: Muhammad Shakir | E26: Supervisor - CRO | F26: Control Center | G26: 49078 | J26: 6027.14 | K26: 6027.14 | L26: =G26*12+H26+J26+K26+I26 -> 600990.28 | M26: 0 | N26: 0 | O26: 0 | P26: 0 | Q26: =VLOOKUP(C26,Incentives!C20:K359,9,FALSE) -> 0 | R26: 0 | S26: 0 | T26: 0 | Y26: 0 | Z26: 5000 | AA26: 5000 | AB26: 0 | AC26: 0 | AD26: 5000 | AE26: 0 | AF26: 0 | AK26: =SUM(L26:AJ26) -> 615990.28 | AL26: =AK26/12 -> 51332.523 | AM26: =IF(AK26<=600000,0, IF(AK26<=1200000,(AK26-600000)*0.01, IF(AK26<=2200000,(AK26-1200000)*0.11+6000, IF(AK26<=3200000,(AK26-2200000)*0.23+116000, IF(AK26<=4100000,(AK26-3200000)*0.3+346000, (AK26-4100000)*0.35+616000))))) *(1+IF(AK26>10000000,9%,0)) -> 159.9028 | AN26: =VLOOKUP(C26,'Paid Tax'!B21:M382,12,FALSE) -> 65.128545 | AO26: =+AM26-AN26 -> 94.774255 | AP26: 6 | AQ26: =+AO26/AP26 -> 15.795709 | AR26: First time tax will be / by 6 | AS26: =-AQ26 -> -15.795709
A27: 20 | B27: Karachi | C27: 10021 | D27: Rahat Gul | E27: Supervisor - Removal | F27: Removal | G27: 46016 | J27: 6346.95 | K27: 6346.95 | L27: =G27*12+H27+J27+K27+I27 -> 564885.9 | M27: 0 | N27: 0 | O27: 0 | P27: 0 | Q27: =VLOOKUP(C27,Incentives!C21:K360,9,FALSE) -> 0 | R27: 0 | S27: 0 | T27: 0 | Y27: 57009 | Z27: 95593 | AA27: 129584 | AB27: 139645 | AC27: 86831 | AD27: 52662 | AE27: 64615 | AF27: 87421 | AK27: =SUM(L27:AJ27) -> 1278245.9 | AL27: =AK27/12 -> 106520.49 | AM27: =IF(AK27<=600000,0, IF(AK27<=1200000,(AK27-600000)*0.01, IF(AK27<=2200000,(AK27-1200000)*0.11+6000, IF(AK27<=3200000,(AK27-2200000)*0.23+116000, IF(AK27<=4100000,(AK27-3200000)*0.3+346000, (AK27-4100000)*0.35+616000))))) *(1+IF(AK27>10000000,9%,0)) -> 14607.049 | AN27: =VLOOKUP(C27,'Paid Tax'!B22:M383,12,FALSE) -> 2499.0677 | AO27: =+AM27-AN27 -> 12107.981 | AP27: 5 | AQ27: =+AO27/AP27 -> 2421.5963 | AS27: =-AQ27 -> -2421.5963
A28: 21 | B28: Karachi | C28: 10023 | D28: Syed Asad Raza | E28: Supervisor - CR | F28: Control Center | G28: 42989 | J28: 5279.4 | K28: 5279.4 | L28: =G28*12+H28+J28+K28+I28 -> 526426.8 | M28: 0 | N28: 0 | O28: 0 | P28: 0 | Q28: =VLOOKUP(C28,Incentives!C22:K361,9,FALSE) -> 0 | R28: 0 | S28: 0 | T28: 0 | Y28: 0 | Z28: 0 | AA28: 0 | AB28: 0 | AC28: 0 | AD28: 0 | AE28: 5000 | AF28: 0 | AK28: =SUM(L28:AJ28) -> 531426.8 | AL28: =AK28/12 -> 44285.567 | AM28: =IF(AK28<=600000,0, IF(AK28<=1200000,(AK28-600000)*0.01, IF(AK28<=2200000,(AK28-1200000)*0.11+6000, IF(AK28<=3200000,(AK28-2200000)*0.23+116000, IF(AK28<=4100000,(AK28-3200000)*0.3+346000, (AK28-4100000)*0.35+616000))))) *(1+IF(AK28>10000000,9%,0)) -> 0 | AN28: =VLOOKUP(C28,'Paid Tax'!B23:M384,12,FALSE) -> 0 | AO28: =+AM28-AN28 -> 0 | AP28: 5 | AQ28: =+AO28/AP28 -> 0 | AS28: =-AQ28 -> 0
A29: 22 | B29: Karachi | C29: 10533 | D29: Dawood Bose | E29: CRO | F29: Control Center | G29: 34000 | J29: 0 | K29: 0 | L29: =G29*12+H29+J29+K29+I29 -> 408000 | M29: 0 | N29: 0 | O29: 0 | P29: 0 | Q29: =VLOOKUP(C29,Incentives!C23:K362,9,FALSE) -> 0 | R29: 0 | S29: 0 | T29: 0 | Y29: 4000 | Z29: 0 | AA29: 0 | AB29: 4000 | AC29: 0 | AD29: 4000 | AE29: 0 | AF29: 0 | AK29: =SUM(L29:AJ29) -> 420000 | AL29: =AK29/12 -> 35000 | AM29: =IF(AK29<=600000,0, IF(AK29<=1200000,(AK29-600000)*0.01, IF(AK29<=2200000,(AK29-1200000)*0.11+6000, IF(AK29<=3200000,(AK29-2200000)*0.23+116000, IF(AK29<=4100000,(AK29-3200000)*0.3+346000, (AK29-4100000)*0.35+616000))))) *(1+IF(AK29>10000000,9%,0)) -> 0 | AN29: =VLOOKUP(C29,'Paid Tax'!B24:M385,12,FALSE) -> 0 | AO29: =+AM29-AN29 -> 0 | AP29: 5 | AQ29: =+AO29/AP29 -> 0 | AS29: =-AQ29 -> 0
A30: 23 | B30: Karachi | C30: 10473 | D30: Noman Khan | E30: CRO | F30: Control Center | G30: 33900 | J30: 3900 | K30: 3900 | L30: =G30*12+H30+J30+K30+I30 -> 414600 | M30: 0 | N30: 0 | O30: 0 | P30: 0 | Q30: =VLOOKUP(C30,Incentives!C24:K363,9,FALSE) -> 0 | R30: 0 | S30: 0 | T30: 0 | Y30: 0 | Z30: 0 | AA30: 0 | AB30: 0 | AC30: 0 | AD30: 0 | AE30: 0 | AF30: 0 | AK30: =SUM(L30:AJ30) -> 414600 | AL30: =AK30/12 -> 34550 | AM30: =IF(AK30<=600000,0, IF(AK30<=1200000,(AK30-600000)*0.01, IF(AK30<=2200000,(AK30-1200000)*0.11+6000, IF(AK30<=3200000,(AK30-2200000)*0.23+116000, IF(AK30<=4100000,(AK30-3200000)*0.3+346000, (AK30-4100000)*0.35+616000))))) *(1+IF(AK30>10000000,9%,0)) -> 0 | AN30: =VLOOKUP(C30,'Paid Tax'!B25:M386,12,FALSE) -> 0 | AO30: =+AM30-AN30 -> 0 | AP30: 5 | AQ30: =+AO30/AP30 -> 0 | AS30: =-AQ30 -> 0
A31: 24 | B31: Karachi | C31: 10511 | D31: Harkas Basharat | E31: CRO | F31: Control Center | G31: 31000 | J31: 0 | K31: 0 | L31: =G31*12+H31+J31+K31+I31 -> 372000 | M31: 0 | N31: 0 | O31: 0 | P31: 0 | Q31: =VLOOKUP(C31,Incentives!C25:K364,9,FALSE) -> 0 | R31: 0 | S31: 0 | T31: 0 | Y31: 0 | Z31: 0 | AA31: 0 | AB31: 0 | AC31: 3000 | AD31: 0 | AE31: 0 | AF31: 0 | AK31: =SUM(L31:AJ31) -> 375000 | AL31: =AK31/12 -> 31250 | AM31: =IF(AK31<=600000,0, IF(AK31<=1200000,(AK31-600000)*0.01, IF(AK31<=2200000,(AK31-1200000)*0.11+6000, IF(AK31<=3200000,(AK31-2200000)*0.23+116000, IF(AK31<=4100000,(AK31-3200000)*0.3+346000, (AK31-4100000)*0.35+616000))))) *(1+IF(AK31>10000000,9%,0)) -> 0 | AN31: =VLOOKUP(C31,'Paid Tax'!B26:M387,12,FALSE) -> 0 | AO31: =+AM31-AN31 -> 0 | AP31: 5 | AQ31: =+AO31/AP31 -> 0 | AS31: =-AQ31 -> 0
A32: 25 | B32: Karachi | C32: 10512 | D32: Alishba Naveed | E32: CRO | F32: Control Center | G32: 36000 | J32: 0 | K32: 0 | L32: =G32*12+H32+J32+K32+I32 -> 432000 | M32: 0 | N32: 0 | O32: 0 | P32: 0 | Q32: =VLOOKUP(C32,Incentives!C26:K365,9,FALSE) -> 0 | R32: 0 | S32: 0 | T32: 0 | Y32: 0 | Z32: 5000 | AA32: 0 | AB32: 0 | AC32: 0 | AD32: 0 | AE32: 1000 | AF32: 0 | AK32: =SUM(L32:AJ32) -> 438000 | AL32: =AK32/12 -> 36500 | AM32: =IF(AK32<=600000,0, IF(AK32<=1200000,(AK32-600000)*0.01, IF(AK32<=2200000,(AK32-1200000)*0.11+6000, IF(AK32<=3200000,(AK32-2200000)*0.23+116000, IF(AK32<=4100000,(AK32-3200000)*0.3+346000, (AK32-4100000)*0.35+616000))))) *(1+IF(AK32>10000000,9%,0)) -> 0 | AN32: =VLOOKUP(C32,'Paid Tax'!B27:M388,12,FALSE) -> 0 | AO32: =+AM32-AN32 -> 0 | AP32: 5 | AQ32: =+AO32/AP32 -> 0 | AS32: =-AQ32 -> 0
A33: 26 | B33: Karachi | C33: 10489 | D33: Muhammad Ayan Ateeb | E33: CRO | F33: Control Center | G33: 33900 | J33: 3900 | K33: 3900 | L33: =G33*12+H33+J33+K33+I33 -> 414600 | M33: 0 | N33: 0 | O33: 0 | P33: 0 | Q33: =VLOOKUP(C33,Incentives!C27:K366,9,FALSE) -> 0 | R33: 0 | S33: 0 | T33: 0 | Y33: 0 | Z33: 0 | AA33: 0 | AB33: 0 | AC33: 1000 | AD33: 0 | AE33: 0 | AF33: 0 | AK33: =SUM(L33:AJ33) -> 415600 | AL33: =AK33/12 -> 34633.333 | AM33: =IF(AK33<=600000,0, IF(AK33<=1200000,(AK33-600000)*0.01, IF(AK33<=2200000,(AK33-1200000)*0.11+6000, IF(AK33<=3200000,(AK33-2200000)*0.23+116000, IF(AK33<=4100000,(AK33-3200000)*0.3+346000, (AK33-4100000)*0.35+616000))))) *(1+IF(AK33>10000000,9%,0)) -> 0 | AN33: =VLOOKUP(C33,'Paid Tax'!B28:M389,12,FALSE) -> 0 | AO33: =+AM33-AN33 -> 0 | AP33: 5 | AQ33: =+AO33/AP33 -> 0 | AS33: =-AQ33 -> 0
A34: 27 | B34: Karachi | C34: 10437 | D34: Yashdial | E34: CRO | F34: Control Center | G34: 33900 | J34: 3900 | K34: 3900 | L34: =G34*12+H34+J34+K34+I34 -> 414600 | M34: 0 | N34: 0 | O34: 0 | P34: 0 | Q34: =VLOOKUP(C34,Incentives!C28:K367,9,FALSE) -> 0 | R34: 0 | S34: 0 | T34: 0 | Y34: 0 | Z34: 1000 | AA34: 3000 | AB34: 0 | AC34: 0 | AD34: 3000 | AE34: 3000 | AF34: 0 | AK34: =SUM(L34:AJ34) -> 424600 | AL34: =AK34/12 -> 35383.333 | AM34: =IF(AK34<=600000,0, IF(AK34<=1200000,(AK34-600000)*0.01, IF(AK34<=2200000,(AK34-1200000)*0.11+6000, IF(AK34<=3200000,(AK34-2200000)*0.23+116000, IF(AK34<=4100000,(AK34-3200000)*0.3+346000, (AK34-4100000)*0.35+616000))))) *(1+IF(AK34>10000000,9%,0)) -> 0 | AN34: =VLOOKUP(C34,'Paid Tax'!B29:M390,12,FALSE) -> 0 | AO34: =+AM34-AN34 -> 0 | AP34: 5 | AQ34: =+AO34/AP34 -> 0 | AS34: =-AQ34 -> 0
A35: 28 | B35: Karachi | C35: 10288 | D35: Muhammad Zakir | E35: Manager, IT | F35: Information Technology | G35: 170000 | J35: 50000 | K35: 50000 | L35: =G35*12+H35+J35+K35+I35 -> 2140000 | M35: 0 | N35: 0 | O35: 0 | P35: 0 | Q35: =VLOOKUP(C35,Incentives!C29:K368,9,FALSE) -> 0 | R35: 0 | S35: 0 | T35: 0 | Y35: 0 | Z35: 0 | AA35: 0 | AB35: 0 | AC35: 0 | AD35: 0 | AE35: 0 | AF35: 0 | AK35: =SUM(L35:AJ35) -> 2140000 | AL35: =AK35/12 -> 178333.33 | AM35: =IF(AK35<=600000,0, IF(AK35<=1200000,(AK35-600000)*0.01, IF(AK35<=2200000,(AK35-1200000)*0.11+6000, IF(AK35<=3200000,(AK35-2200000)*0.23+116000, IF(AK35<=4100000,(AK35-3200000)*0.3+346000, (AK35-4100000)*0.35+616000))))) *(1+IF(AK35>10000000,9%,0)) -> 109400 | AN35: =VLOOKUP(C35,'Paid Tax'!B30:M391,12,FALSE) -> 63608.333 | AO35: =+AM35-AN35 -> 45791.667 | AP35: 5 | AQ35: =+AO35/AP35 -> 9158.3333 | AS35: =-AQ35 -> -9158.3333
A36: 29 | B36: Karachi | C36: 10467 | D36: Waseem ul Haq | E36: Sr. IT Support Executive | F36: Information Technology | G36: 58500 | J36: 8500 | K36: 8500 | L36: =G36*12+H36+J36+K36+I36 -> 719000 | M36: 0 | N36: 0 | O36: 0 | P36: 0 | Q36: =VLOOKUP(C36,Incentives!C30:K369,9,FALSE) -> 0 | R36: 0 | S36: 0 | T36: 0 | Y36: 0 | Z36: 0 | AA36: 0 | AB36: 0 | AC36: 0 | AD36: 0 | AE36: 0 | AF36: 0 | AK36: =SUM(L36:AJ36) -> 719000 | AL36: =AK36/12 -> 59916.667 | AM36: =IF(AK36<=600000,0, IF(AK36<=1200000,(AK36-600000)*0.01, IF(AK36<=2200000,(AK36-1200000)*0.11+6000, IF(AK36<=3200000,(AK36-2200000)*0.23+116000, IF(AK36<=4100000,(AK36-3200000)*0.3+346000, (AK36-4100000)*0.35+616000))))) *(1+IF(AK36>10000000,9%,0)) -> 1190 | AN36: =VLOOKUP(C36,'Paid Tax'!B31:M392,12,FALSE) -> 291.70455 | AO36: =+AM36-AN36 -> 898.29545 | AP36: 5 | AQ36: =+AO36/AP36 -> 179.65909 | AS36: 0 | AT36: Resigned
A37: 30 | B37: Karachi | C37: 10028 | D37: Tariq Shahzad | E37: Director - Marketing & Sales | F37: Sales & Marketing | G37: 442651 | J37: 80000 | K37: 80000 | L37: =G37*12+H37+J37+K37+I37 -> 5471812 | M37: 0 | N37: 0 | O37: 0 | P37: 0 | Q37: =VLOOKUP(C37,Incentives!C31:K370,9,FALSE) -> 0 | R37: 0 | S37: 0 | T37: 0 | Y37: 0 | Z37: 118716 | AA37: 93128 | AB37: 0 | AC37: 89067 | AD37: 0 | AE37: 0 | AF37: 0 | AK37: =SUM(L37:AJ37) -> 5772723 | AL37: =AK37/12 -> 481060.25 | AM37: =IF(AK37<=600000,0, IF(AK37<=1200000,(AK37-600000)*0.01, IF(AK37<=2200000,(AK37-1200000)*0.11+6000, IF(AK37<=3200000,(AK37-2200000)*0.23+116000, IF(AK37<=4100000,(AK37-3200000)*0.3+346000, (AK37-4100000)*0.35+616000))))) *(1+IF(AK37>10000000,9%,0)) -> 1201453 | AN37: =VLOOKUP(C37,'Paid Tax'!B32:M393,12,FALSE) -> 689002.42 | AO37: =+AM37-AN37 -> 512450.63 | AP37: 5 | AQ37: =+AO37/AP37 -> 102490.13 | AS37: =-AQ37 -> -102490.13
A38: 31 | B38: Karachi | C38: 10030 | D38: Muhammad Umer Azeem | E38: Manager, Sales & Marketing | F38: Sales & Marketing | G38: 123614 | J38: 40000 | K38: 40000 | L38: =G38*12+H38+J38+K38+I38 -> 1563368 | M38: 0 | N38: 0 | O38: 0 | P38: 0 | Q38: =VLOOKUP(C38,Incentives!C32:K371,9,FALSE) -> 0 | R38: 0 | S38: 0 | T38: 0 | Y38: 8884 | Z38: 96506 | AA38: 237930 | AB38: 9736 | AC38: 199126 | AD38: 192710 | AE38: 5613 | AF38: 3375 | AK38: =SUM(L38:AJ38) -> 2317248 | AL38: =AK38/12 -> 193104 | AM38: =IF(AK38<=600000,0, IF(AK38<=1200000,(AK38-600000)*0.01, IF(AK38<=2200000,(AK38-1200000)*0.11+6000, IF(AK38<=3200000,(AK38-2200000)*0.23+116000, IF(AK38<=4100000,(AK38-3200000)*0.3+346000, (AK38-4100000)*0.35+616000))))) *(1+IF(AK38>10000000,9%,0)) -> 142967.04 | AN38: =VLOOKUP(C38,'Paid Tax'!B33:M394,12,FALSE) -> 64769.479 | AO38: =+AM38-AN38 -> 78197.561 | AP38: 5 | AQ38: =+AO38/AP38 -> 15639.512 | AS38: =-AQ38 -> -15639.512
A39: 32 | B39: Karachi | C39: 10031 | D39: Hassan Mustafa | E39: Assistant Manager, Sales &Marketing | F39: Sales & Marketing | G39: =75640 -> 75640 | H39: =20000*10 -> 200000 | J39: =40000+40000+40000+40000 -> 160000 | K39: 0 | L39: =G39*12+H39+J39+K39+I39 -> 1267680 | M39: 0 | N39: 0 | O39: 0 | P39: 0 | Q39: =VLOOKUP(C39,Incentives!C33:K372,9,FALSE) -> 0 | R39: 0 | S39: 0 | T39: 0 | Y39: 0 | Z39: 0 | AA39: 30525 | AB39: 0 | AC39: 12400 | AD39: 0 | AE39: 3248 | AF39: 1416 | AK39: =SUM(L39:AJ39) -> 1315269 | AL39: =AK39/12 -> 109605.75 | AM39: =IF(AK39<=600000,0, IF(AK39<=1200000,(AK39-600000)*0.01, IF(AK39<=2200000,(AK39-1200000)*0.11+6000, IF(AK39<=3200000,(AK39-2200000)*0.23+116000, IF(AK39<=4100000,(AK39-3200000)*0.3+346000, (AK39-4100000)*0.35+616000))))) *(1+IF(AK39>10000000,9%,0)) -> 18679.59 | AN39: =VLOOKUP(C39,'Paid Tax'!B34:M395,12,FALSE) -> 7612.7379 | AO39: =+AM39-AN39 -> 11066.852 | AP39: 5 | AQ39: =+AO39/AP39 -> 2213.3704 | AS39: =-AQ39 -> -2213.3704
A40: 33 | B40: Karachi | C40: 10032 | D40: Farjad Latif | E40: Assistant Manager | F40: Sales & Marketing | G40: 75843 | J40: 17500 | K40: 17500 | L40: =G40*12+H40+J40+K40+I40 -> 945116 | M40: 0 | N40: 0 | O40: 0 | P40: 0 | Q40: =VLOOKUP(C40,Incentives!C34:K373,9,FALSE) -> 0 | R40: 0 | S40: 0 | T40: 0 | Y40: 0 | Z40: 10075 | AA40: 8375 | AB40: 4315 | AC40: 3828 | AD40: 3652 | AE40: 5637 | AF40: 2219 | AK40: =SUM(L40:AJ40) -> 983217 | AL40: =AK40/12 -> 81934.75 | AM40: =IF(AK40<=600000,0, IF(AK40<=1200000,(AK40-600000)*0.01, IF(AK40<=2200000,(AK40-1200000)*0.11+6000, IF(AK40<=3200000,(AK40-2200000)*0.23+116000, IF(AK40<=4100000,(AK40-3200000)*0.3+346000, (AK40-4100000)*0.35+616000))))) *(1+IF(AK40>10000000,9%,0)) -> 3832.17 | AN40: =VLOOKUP(C40,'Paid Tax'!B35:M396,12,FALSE) -> 2156.7395 | AO40: =+AM40-AN40 -> 1675.4305 | AP40: 5 | AQ40: =+AO40/AP40 -> 335.0861 | AS40: =-AQ40 -> -335.0861
...

Sheet Paid Tax
A2: S.no | B2: Employee ID | C2: Name | D2: Designation | E2: Department | F2: paid Tax - Jul | G2: paid Tax - Aug | H2: paid Tax - Sep | I2: paid Tax - oct | J2: paid Tax - Nov | K2: paid Tax - Dec | L2: paid Tax - Jan | M2: Sum
A3: 1 | B3: 10001 | C3: Syed Salman Hussain | D3: CEO | E3: Management | F3: 1175113.4 | G3: 1175113.4 | H3: 1175113.5 | I3: 1175113.5 | J3: 1175113.5 | K3: 1175113.5 | L3: 1175113.5 | M3: =SUM(F3:L3) -> 8225794.2
A4: 2 | B4: 20001 | C4: Ahmed Farid Bokhari | D4: Director | E4: Management | F4: 74881.1 | G4: 74881.1 | H4: 74881.1 | I4: 74881.1 | J4: 74881.1 | K4: 74881.1 | L4: 74881.1 | M4: =SUM(F4:L4) -> 524167.7
A5: 3 | B5: 10520 | C5: Nadeem Qasim | D5: Personal Assistant | E5: Management | F5: 350 | G5: 350 | H5: 350 | I5: 350 | J5: 350 | K5: 350 | L5: 350 | M5: =SUM(F5:L5) -> 2450
A6: 4 | B6: 10002 | C6: Ubaid Ullah | D6: Head, Admin | E6: Admin | F6: 5507.2619 | G6: 5646.0494 | H6: 5646.0494 | I6: 5646.0494 | J6: 5646.0494 | K6: 5646.0494 | L6: 5646.0494 | M6: =SUM(F6:L6) -> 39383.558
A7: 5 | B7: 10003 | C7: Furqan | D7: Supervisor, Admin | E7: Admin | F7: 308.43667 | G7: 315.70939 | H7: 315.70939 | I7: 315.70939 | J7: 315.70939 | K7: 315.70939 | L7: 315.70939 | M7: =SUM(F7:L7) -> 2202.693
A8: 6 | B8: 10418 | C8: Syed Omar Farooq Naqvi | D8: Officer, Admin | E8: Admin | F8: 0 | G8: 0 | H8: 0 | I8: 0 | J8: 0 | K8: 0 | L8: 0 | M8: =SUM(F8:L8) -> 0
A9: 7 | B9: 10006 | C9: Humna Altamash Yousuf | D9: Head - HR & Cultural Development | E9: Human Resources | F9: 5364.0533 | G9: 5564.0533 | H9: 5564.0533 | I9: 5564.0533 | J9: 5564.0533 | K9: 5564.0533 | L9: 5564.0533 | M9: =SUM(F9:L9) -> 38748.373
A10: 8 | B10: 10008 | C10: Muhammad Fahad | D10: Head - Financial Governance & Compliance | E10: Accounts & Finance | F10: 40416.133 | G10: 42052.497 | H10: 42052.497 | I10: 42052.497 | J10: 42052.497 | K10: 42052.497 | L10: 42052.497 | M10: =SUM(F10:L10) -> 292731.12
A11: 9 | B11: 10009 | C11: Muhammad Shaukat | D11: Supervisor, Recovery & Collection | E11: Accounts & Finance | F11: 84.16 | G11: 92.341818 | H11: 92.341818 | I11: 92.341818 | J11: 92.341818 | K11: 92.341818 | L11: 92.341818 | M11: =SUM(F11:L11) -> 638.21091
A12: 10 | B12: 10010 | C12: Vivian Charles Paul | D12: Head - Corporate Services & Renewal | E12: Corporate Services | F12: 26057.195 | G12: 27830.202 | H12: 28326.703 | I12: 28870.628 | J12: 29692.159 | K12: 30484.416 | L12: 31761.616 | M12: =SUM(F12:L12) -> 203022.92
A13: 11 | B13: 10011 | C13: Sidra | D13: Manager, CS | E13: Corporate Services | F13: 491.37667 | G13: 507.30394 | H13: 507.30394 | I13: 507.30394 | J13: 507.30394 | K13: 507.30394 | L13: 507.30394 | M13: =SUM(F13:L13) -> 3535.2003
A14: 12 | B14: 10494 | C14: Dawood | D14: Supervisor, CS | E14: Corporate Services | F14: 42.041667 | G14: 50.814394 | H14: 54.814394 | I14: 54.814394 | J14: 54.814394 | K14: 54.814394 | L14: 54.814394 | M14: =SUM(F14:L14) -> 366.92803
... A341: 339 | B341: 10695 | C341: Mirza Umair Baig | D341: Technician | E341: Technical | F341: 0 | G341: 0 | H341: 0 | I341: 0 | J341: 0 | K341: 0 | L341: 0 | M341: =SUM(F341:L341) -> 0
A342: 340 | B342: 10696 | C342: Obaidullah | D342: CRO | E342: Control Room | J342: 0 | K342: 0 | L342: 0 | M342: =SUM(F342:L342) -> 0
A343: 341 | B343: 10697 | C343: Abdul Sameer | D343: Diagnostics Officer | E343: Diagnostics & Harness | J343: 0 | K343: 0 | L343: 0 | M343: =SUM(F343:L343) -> 0
A344: 342 | B344: 10698 | C344: Fahim Ayoob | D344: Technician | E344: Technical | J344: 0 | K344: 0 | L344: 0 | M344: =SUM(F344:L344) -> 0
A345: 343 | B345: 10699 | C345: Sheeraz Mehdi | D345: CRO | E345: Control Room | J345: 0 | K345: 0 | L345: 0 | M345: =SUM(F345:L345) -> 0
A346: 344 | B346: 10700 | C346: Muhammad Zia | D346: CRO | E346: Control Room | J346: 0 | K346: 0 | L346: 0 | M346: =SUM(F346:L346) -> 0
A347: 345 | B347: 10701 | C347: Syed Hamza Ali Kazmi | D347: Coordinator | E347: Technical | J347: 0 | K347: 0 | L347: 0 | M347: =SUM(F347:L347) -> 0
A348: 346 | B348: 10702 | C348: Danish Nadeem | D348: Technician | E348: Technical | J348: 0 | K348: 0 | L348: 0 | M348: =SUM(F348:L348) -> 0
A349: 347 | B349: 10703 | C349: Nazra Nazar | D349: Collection Officer | E349: Removal | J349: 0 | K349: 0 | L349: 0 | M349: =SUM(F349:L349) -> 0
A350: 348 | B350: 10704 | C350: Muhammad Agha Jaffar | D350: Collection Officer | E350: Removal | J350: 0 | K350: 0 | L350: 0 | M350: =SUM(F350:L350) -> 0
A351: 349 | B351: 10705 | C351: Shakir Ullah | D351: Technician | E351: Technical | K351: 0 | L351: 0 | M351: =SUM(F351:L351) -> 0
A352: 350 | B352: 10708 | C352: Muhammad Hassan | D352: CRO | E352: Control Room | K352: 0 | L352: 0 | M352: =SUM(F352:L352) -> 0
A353: 351 | B353: 10706 | C353: Muhammad Suleman | D353: Technician | E353: Technical | K353: 0 | L353: 0 | M353: =SUM(F353:L353) -> 0
A354: 352 | B354: 10707 | C354: Imran Younis | D354: Manager, Sales | E354: Sales & Marketing | K354: 0 | L354: 500 | M354: =SUM(F354:L354) -> 500
A355: 353 | B355: 10709 | C355: Abdul Aleem Mughal | D355: CRO | E355: Control Room | K355: 0 | L355: 0 | M355: =SUM(F355:L355) -> 0
A356: 354 | B356: 10710 | C356: Khawar Nasir Ali | D356: CRO | E356: Control Room | K356: 0 | L356: 0 | M356: =SUM(F356:L356) -> 0
A357: 355 | B357: 10711 | C357: Muhammad Shehraz | D357: Technician | E357: Technical | K357: 0 | L357: 0 | M357: =SUM(F357:L357) -> 0
A358: 356 | B358: 10712 | C358: Sania Mehboob | D358: MTO, Marketing | E358: Marketing | K358: 0 | L358: 0 | M358: =SUM(F358:L358) -> 0
A359: 357 | B359: 10713 | C359: Jamila Attaria | D359: Finance Officer | E359: Accoucts & Finance | K359: 0 | L359: 0 | M359: =SUM(F359:L359) -> 0
A360: 358 | B360: 10714 | C360: Muhammad Hussain Ali | D360: Digital Sales Officer | E360: Marketing | K360: 0 | L360: 0 | M360: =SUM(F360:L360) -> 0
A361: 359 | B361: 10715 | C361: Abu Hurraira Jadoon | D361: CRO | E361: Control Room | K361: 0 | L361: 0 | M361: =SUM(F361:L361) -> 0
A362: 360 | B362: 10716 | C362: Shahzaib Ahmad | D362: CRO | E362: Control Room | K362: 0 | L362: 0 | M362: =SUM(F362:L362) -> 0
... A365: 363 | B365: 10719 | C365: Anam Sabir | D365: CRO | E365: Control Room | K365: 0 | L365: 0 | M365: =SUM(F365:L365) -> 0
A366: 364 | B366: 10720 | C366: Ruqqaya Azad | D366: CRO | E366: Control Room | L366: 0 | M366: =SUM(F366:L366) -> 0
A367: 365 | B367: 10721 | C367: Mihir | D367: TDD Support Executive | E367: Technology Development | L367: 0 | M367: =SUM(F367:L367) -> 0
A368: 366 | B368: 10722 | C368: Hassan Jabbar | D368: Digital Sales Officer | E368: Marketing | L368: 0 | M368: =SUM(F368:L368) -> 0
A369: 367 | B369: 10723 | C369: Rehan Gull | D369: Technician | E369: Technical | L369: 0 | M369: =SUM(F369:L369) -> 0
...

Sheet Commision 
A1: Employee ID | B1: Name | C1: Designation | D1: Department | E1: 45839 | F1: 45870 | G1: 45901 | H1: 45931 | I1: 45962 | J1: 45992 | K1: 46048 | L1: 46076
A2: 10001 | B2: Syed Salman Hussain | C2: CEO | D2: Management | E2: 0 | F2: 0 | G2: 0 | H2: 0 | I2: 0 | J2: 0 | K2: 0 | L2: 0
A3: 20001 | B3: Ahmed Farid Bokhari | C3: Director | D3: Management | E3: 0 | F3: 0 | G3: 0 | H3: 0 | I3: 0 | J3: 0 | K3: 0 | L3: 0
A4: 10520 | B4: Nadeem Qasim | C4: Personal Assistant | D4: Management | E4: 0 | F4: 0 | G4: 0 | H4: 0 | I4: 0 | J4: 0 | K4: 0 | L4: 0
A5: 10002 | B5: Ubaid Ullah | C5: Head, Admin | D5: Admin | E5: 0 | F5: 0 | G5: 0 | H5: 0 | I5: 0 | J5: 0 | K5: 0 | L5: 0
A6: 10003 | B6: Furqan | C6: Supervisor, Admin | D6: Admin | E6: 0 | F6: 0 | G6: 0 | H6: 0 | I6: 0 | J6: 0 | K6: 0 | L6: 0
A7: 10418 | B7: Syed Omar Farooq Naqvi | C7: Officer, Admin | D7: Admin | E7: 0 | F7: 0 | G7: 0 | H7: 0 | I7: 0 | J7: 0 | K7: 0 | L7: 0
A8: 10006 | B8: Humna Altamash Yousuf | C8: Head - HR & Cultural Development | D8: Human Resources | E8: 0 | F8: 0 | G8: 0 | H8: 0 | I8: 0 | J8: 0 | K8: 0 | L8: 0
A9: 10008 | B9: Muhammad Fahad | C9: Head - Financial Governance & Compliance | D9: Accounts & Finance | E9: 0 | F9: 0 | G9: 0 | H9: 0 | I9: 0 | J9: 0 | K9: 0 | L9: 0
A10: 10009 | B10: Muhammad Shaukat | C10: Supervisor, Recovery & Collection | D10: Accounts & Finance | E10: 0 | F10: 0 | G10: 0 | H10: 0 | I10: 0 | J10: 0 | K10: 0 | L10: 0
A11: 10010 | B11: Vivian Charles Paul | C11: Head - Corporate Services & Renewal | D11: Corporate Services | E11: 19310 | F11: 44796 | G11: 21587 | H11: 21284 | I11: 25915 | J11: 18486 | K11: 25544 | L11: 35743
A12: 10011 | B12: Sidra | C12: Manager, CS | D12: Corporate Services | E12: 0 | F12: 0 | G12: 0 | H12: 0 | I12: 0 | J12: 0 | K12: 0 | L12: 0
A13: 10494 | B13: Dawood | C13: Supervisor, CS | D13: Corporate Services | E13: 0 | F13: 3000 | G13: 4000 | H13: 0 | I13: 0 | J13: 0 | K13: 0 | L13: 0
... A116: 10352 | B116: Arbaz Sohail | C116: Jr. Harness Technician | D116: Diagnostics & Harness | E116: 0 | F116: 0 | G116: 0 | H116: 0 | I116: 0 | J116: 0 | K116: 0 | L116: 0
A117: 10290 | B117: Syed Sajid Hussain Shah | C117: Sales Executive | D117: Sales & Marketing | E117: 5063 | F117: 86250 | G117: 139843 | H117: 3272 | I117: 4155 | J117: 76856 | K117: =2508+157025 -> 159533 | L117: 1900
A118: 10291 | B118: Abdul Karim Khan | C118: Security Officer | D118: Security department | E118: 0 | F118: 0 | G118: 0 | H118: 0 | I118: 0 | J118: 0 | K118: 0 | L118: 0
A119: 10389 | B119: Faraz Ahmed | C119: Security Officer | D119: Security department | E119: 0 | F119: 0 | G119: 0 | H119: 0 | I119: 0 | J119: 0 | K119: 0 | L119: 0
A120: 10482 | B120: Syed Shabbir Hussain | C120: Head - Security | D120: Security department | E120: 0 | F120: 0 | G120: 0 | H120: 0 | I120: 0 | J120: 0 | K120: 0 | L120: 0
A121: 20005 | B121: Syed Zeeshan Ahmed | C121: Head - Satellite Services/Customer Care | D121: Customer Care | E121: 0 | F121: 0 | G121: 0 | H121: 0 | I121: 0 | J121: 0 | K121: 0 | L121: 0
A122: 20062 | B122: Abdus Subhan | C122: MTO, Andriod | D122: Software Development | E122: 0 | F122: 0 | G122: 0 | H122: 0 | I122: 0 | J122: 0 | K122: 0 | L122: 0
A123: 20007 | B123: Owais Akhlaq | C123: Head - Technical & Product Development | D123: Technology Development | E123: 0 | F123: 0 | G123: 0 | H123: 0 | I123: 0 | J123: 0 | K123: 0 | L123: 0
A124: 20066 | B124: Muhammad Anas | C124: Embedded Engineer | D124: Technology Development | E124: 0 | F124: 0 | G124: 0 | H124: 0 | I124: 0 | J124: 0 | K124: 0 | L124: 0
A125: 20011 | B125: Arshan Ahmed | C125: Technical Support Executive | D125: Technology Development | E125: 0 | F125: 0 | G125: 0 | H125: 0 | I125: 0 | J125: 0 | K125: 0 | L125: 0
A126: 10401 | B126: Kamran Jamal | C126: ERP Manager | D126: Software Development | E126: 0 | F126: 0 | G126: 0 | H126: 0 | I126: 0 | J126: 0 | K126: 0 | L126: 0
A127: 20060 | B127: Muhammad Zeeshan | C127: Software Engineer - II | D127: Software Development | E127: 0 | F127: 0 | G127: 0 | H127: 0 | I127: 0 | J127: 0 | K127: 0 | L127: 0
A128: 10382 | B128: Muhammad Hamza Khan | C128: Sr. Software Engineer - I | D128: Software Development | E128: 0 | F128: 0 | G128: 0 | H128: 0 | I128: 0 | J128: 0 | K128: 0 | L128: 0
A129: 20064 | B129: Rao Aaraf Younus | C129: Software Engineer - II | D129: Software Development | E129: 0 | F129: 0 | G129: 0 | H129: 0 | I129: 0 | J129: 0 | K129: 0 | L129: 0
... A251: 10432 | B251: Tanvir Ahmed | C251: Manager Sales | D251: Sales & Marketing | E251: 0 | F251: 41775 | G251: 16000 | H251: 0 | I251: 9450 | J251: 12040 | K251: 1120 | L251: 0
A252: 10391 | B252: Hannan Ali | C252: Manager Sales | D252: Sales & Marketing | E252: 7342 | F252: 63800 | G252: 297899 | H252: 3185 | I252: 228576 | J252: 74381 | K252: =3153+195075 -> 198228 | L252: 2679
A253: 10102 | B253: Chand Ali Ansari | C253: Office Boy | D253: Admin | E253: 0 | F253: 0 | G253: 0 | H253: 0 | I253: 0 | J253: 0 | K253: 0 | L253: 0
A254: 10103 | B254: Zahid Iqbal | C254: Assistant Manager, Branch | D254: Technical | E254: 0 | F254: 0 | G254: 0 | H254: 0 | I254: 0 | J254: 0 | K254: 0 | L254: 0
A255: 10104 | B255: Muhammad Mughera Ismail | C255: Technician | D255: Technical | E255: 0 | F255: 0 | G255: 0 | H255: 0 | I255: 0 | J255: 0 | K255: 0 | L255: 0
A256: 10107 | B256: Muhammad Ajmal Khan | C256: Technician | D256: Technical | E256: 0 | F256: 0 | G256: 0 | H256: 0 | I256: 0 | J256: 0 | K256: 0 | L256: 0
A257: 10345 | B257: Muhammad Arif | C257: Technician | D257: Technical | E257: 0 | F257: 0 | G257: 0 | H257: 0 | I257: 0 | J257: 0 | K257: 0 | L257: 0
A258: 10292 | B258: Umer Rasheed | C258: Technician | D258: Technical | E258: 0 | F258: 0 | G258: 0 | H258: 0 | I258: 0 | J258: 0 | K258: 0 | L258: 0
A259: 10402 | B259: Irshad Ahmed | C259: Technician | D259: Technical | E259: 0 | F259: 0 | G259: 0 | H259: 0 | I259: 0 | J259: 0 | K259: 0 | L259: 0
A260: 10493 | B260: Ateeq Ur Rehman | C260: Technician | D260: Technical | E260: 0 | F260: 0 | G260: 0 | H260: 0 | I260: 0 | J260: 0 | K260: 0 | L260: 0
A261: 10426 | B261: Ishfaq Ahmed | C261: Technician | D261: Technical | E261: 0 | F261: 0 | G261: 0 | H261: 0 | I261: 0 | J261: 0 | K261: 0 | L261: 0
A262: 10455 | B262: Muhammad Bilal Ali | C262: Technician | D262: Technical | E262: 0 | F262: 0 | G262: 0 | H262: 0 | I262: 0 | J262: 0 | K262: 0 | L262: 0
A263: 10642 | B263: Mubashar Ijaz | C263: Technician | D263: Technical | E263: 0 | F263: 0 | G263: 0 | H263: 0 | I263: 0 | J263: 0 | K263: 0 | L263: 0
...

Sheet Incentives
A1: S. no | B1: Region | C1: Employee ID | D1: Name | E1: Designation | F1: Department | G1: 45839 | H1: 45870 | I1: 45901 | J1: 45931 | K1: 45962 | L1: 45992 | M1: 46023 | N1: 46054
A2: 1 | B2: Karachi | C2: 10001 | D2: Syed Salman Hussain | E2: CEO | F2: Management | G2: 0 | H2: 0 | I2: 0 | J2: 0 | K2: 0 | L2: 0 | M2: 0 | N2: 0
A3: 2 | B3: Karachi | C3: 20001 | D3: Ahmed Farid Bokhari | E3: Director | F3: Management | G3: 0 | H3: 0 | I3: 0 | J3: 0 | K3: 0 | L3: 0 | M3: 0 | N3: 0
A4: 3 | B4: Karachi | C4: 10520 | D4: Nadeem Qasim | E4: Personal Assistant | F4: Management | G4: 0 | H4: 0 | I4: 0 | J4: 0 | K4: 0 | L4: 0 | M4: 0 | N4: 0
A5: 4 | B5: Karachi | C5: 10002 | D5: Ubaid Ullah | E5: Head, Admin | F5: Admin | G5: 0 | H5: 0 | I5: 0 | J5: 0 | K5: 0 | L5: 0 | M5: 0 | N5: 0
A6: 5 | B6: Karachi | C6: 10003 | D6: Furqan | E6: Supervisor, Admin | F6: Admin | G6: 0 | H6: 0 | I6: 0 | J6: 0 | K6: 0 | L6: 0 | M6: 0 | N6: 0
A7: 6 | B7: Karachi | C7: 10418 | D7: Syed Omar Farooq Naqvi | E7: Officer, Admin | F7: Admin | G7: 0 | H7: 0 | I7: 0 | J7: 0 | K7: 0 | L7: 0 | M7: 0 | N7: 0
A8: 7 | B8: Karachi | C8: 10006 | D8: Humna Altamash Yousuf | E8: Head - HR & Cultural Development | F8: Human Resources | G8: 0 | H8: 0 | I8: 0 | J8: 0 | K8: 0 | L8: 0 | M8: 0 | N8: 0
A9: 8 | B9: Karachi | C9: 10008 | D9: Muhammad Fahad | E9: Head - Financial Governance & Compliance | F9: Accounts & Finance | G9: 0 | H9: 0 | I9: 0 | J9: 0 | K9: 0 | L9: 0 | M9: 0 | N9: 0
A10: 9 | B10: Karachi | C10: 10009 | D10: Muhammad Shaukat | E10: Supervisor, Recovery & Collection | F10: Accounts & Finance | G10: 0 | H10: 0 | I10: 0 | J10: 0 | K10: 0 | L10: 0 | M10: 0 | N10: 0
A11: 10 | B11: Karachi | C11: 10010 | D11: Vivian Charles Paul | E11: Head - Corporate Services & Renewal | F11: Corporate Services | G11: 0 | H11: 0 | I11: 0 | J11: 0 | K11: 0 | L11: 0 | M11: 0 | N11: 0
A12: 11 | B12: Karachi | C12: 10011 | D12: Sidra | E12: Manager, CS | F12: Corporate Services | G12: 0 | H12: 0 | I12: 0 | J12: 0 | K12: 0 | L12: 0 | M12: 0 | N12: 0
A13: 12 | B13: Karachi | C13: 10494 | D13: Dawood | E13: Supervisor, CS | F13: Corporate Services | G13: 0 | H13: 0 | I13: 0 | J13: 0 | K13: 0 | L13: 0 | M13: 0 | N13: 0
... A288: 287 | B288: Multan | C288: 10129 | D288: Muhammad Yaseen | E288: Technician | F288: Technical | G288: 1620 | H288: 1770 | I288: 0 | J288: 0 | K288: 0 | L288: 0 | M288: 0 | N288: 0
A289: 288 | B289: Karachi | C289: 10643 | D289: Muhammad Huzaifa Khan | E289: Business Development Officer | F289: Sales & Marketing | H289: 0 | I289: 0 | J289: 0 | K289: 0 | L289: 0 | M289: 0 | N289: 0
A290: 289 | B290: Karachi | C290: 10645 | D290: Umair Khan | E290: Technician | F290: Technical | H290: 3280 | I290: 6060 | J290: 30240 | K290: 26400 | L290: 27040 | M290: 43380 | N290: 48240
A291: 290 | B291: Karachi | C291: 10646 | D291: Muhammad Ayaz | E291: Sr. Technical Support | F291: Technology Development | H291: 0 | I291: 0 | J291: 0 | K291: 0 | L291: 0 | M291: 0 | N291: 0
A292: 291 | B292: Karachi | C292: 10647 | D292: Israr Ahmed | E292: Harness Technician | F292: Diagnostics & Harness | H292: 0 | I292: 0 | J292: 0 | K292: 0 | L292: 0 | M292: 0 | N292: 0
A293: 292 | B293: Hyderabad | C293: 10644 | D293: Amir Ahmed Qureshi | E293: Supervisor, Technical | F293: Technical | H293: 0 | I293: 0 | J293: 0 | K293: 1260 | L293: 4740 | M293: 1530 | N293: 2010
A294: 293 | B294: Karachi | C294: 10390 | D294: Muhammad Sheheryar Izhar | E294: Dot Net developer | F294: Software Development | H294: 0 | I294: 0 | J294: 0 | K294: 0 | L294: 0 | M294: 0 | N294: 0
A295: 294 | B295: Vehari | C295: 10648 | D295: Muhammad Mohsin | E295: Technician | F295: Technical | H295: 0 | I295: 1710 | J295: 0 | K295: 900 | L295: 1170 | M295: 1350 | N295: 1650
A296: 295 | B296: Karachi | C296: 10649 | D296: Ninta | E296: Front Desk Officer | F296: Administration | H296: 0 | I296: 0 | J296: 0 | K296: 0 | L296: 0 | M296: 0 | N296: 0
A297: 296 | B297: Karachi | C297: 10650 | D297: Zaynab Mustafa | E297: Collection Officer | F297: Renewal Department | H297: 0 | I297: 0 | J297: 0 | K297: 0 | L297: 0 | M297: 0 | N297: 0
A298: 297 | B298: Karachi | C298: 10651 | D298: Muhammad Sami | E298: Collection Officer | F298: Renewal Department | H298: 0 | I298: 0 | J298: 0 | K298: 0 | L298: 0 | M298: 0 | N298: 0
A299: 298 | B299: Karachi | C299: 10652 | D299: Elisha Rayan | E299: CRO | F299: Control room | H299: 0 | I299: 0 | J299: 0 | K299: 0 | L299: 0 | M299: 0 | N299: 0
A300: 299 | B300: Karachi | C300: 10653 | D300: Abdul Samad Khan | E300: CRO | F300: Control room | H300: 0 | I300: 0 | J300: 0 | K300: 0 | L300: 0 | M300: 0 | N300: 0
... A321: 320 | B321: Islamabad | C321: 10669 | D321: Khurram Shahbaz | E321: Technician | F321: Technical | H321: 0 | I321: 0 | J321: 0 | K321: 1830 | L321: 4615 | M321: 1770 | N321: 0
A322: 321 | B322: Faisalabad | C322: 10675 | D322: Iftikhar Haider | E322: Technician | F322: Technical | J322: 0 | K322: 1050 | L322: 1410 | M322: 1980 | N322: 1890
A323: 322 | B323: Karachi | C323: 10676 | D323: Muhammad Arbab | E323: Technician | F323: Technical | J323: 0 | K323: 5590 | L323: 27900 | M323: 9700 | N323: 11400
A324: 323 | B324: Karachi | C324: 10677 | D324: Majid Ali | E324: Technician | F324: Technical | H324: 0 | I324: 0 | J324: 0 | K324: 990 | L324: 0 | M324: 0 | N324: 0
A325: 324 | B325: Karachi | C325: 10678 | D325: Aliza Waleed | E325: Collection Officer | F325: Renewal Department | J325: 0 | K325: 0 | L325: 0 | M325: 0 | N325: 0
A326: 325 | B326: Karachi | C326: 10679 | D326: Warda Khan | E326: Digital Sales Officer | F326: Marketing | J326: 0 | K326: 0 | L326: 0 | M326: 0 | N326: 0
A327: 326 | B327: Karachi | C327: 10680 | D327: Kanwar Zain Shahid | E327: CRO | F327: Control Center | H327: 0 | I327: 0 | J327: 0 | K327: 0 | L327: 0 | M327: 0 | N327: 0
A328: 327 | B328: Karachi | C328: 10681 | D328: Muhammad Ramzan | E328: Technician | F328: Technical | J328: 0 | K328: 1500 | L328: 14160 | M328: 1680 | N328: 3430
A329: 328 | B329: Lahore | C329: 10682 | D329: Arsalan Ali | E329: Technician | F329: Technical | J329: 0 | K329: 1350 | L329: 1740 | M329: 5170 | N329: 1800
A330: 329 | B330: Karachi | C330: 10683 | D330: Rashid Qureshi | E330: Housekeeping Staff | F330: Administration | H330: 0 | I330: 0 | J330: 0 | K330: 0 | L330: 0 | M330: 0 | N330: 0
A331: 330 | B331: Karachi | C331: 10684 | D331: Fiza Sheikh | E331: Collection Officer | F331: Renewal Department | J331: 0 | K331: 0 | L331: 0 | M331: 0 | N331: 0
A332: 331 | B332: Karachi | C332: 10685 | D332: Ibad | E332: Harness Technician | F332: Diagnostics & Harness | J332: 0 | K332: 0 | L332: 0 | M332: 0 | N332: 0
A333: 332 | B333: Karachi | C333: 10686 | D333: Saddam Ali | E333: Coordinator | F333: Technical | H333: 0 | I333: 0 | J333: 0 | K333: 0 | L333: 0 | M333: 0 | N333: 0
A334: 333 | B334: Khanpur | C334: 10689 | D334: Tanveer Ali | E334: Technician | F334: Technical | J334: 0 | K334: 0 | L334: 1410 | M334: 1950 | N334: 1470
...

Sheet Comission Jul 25
A1: S.No | B1: Drawer Name | C1: Bank | D1: Cheque No. | E1: Receiving Month | F1: Finance Date | G1: Detail | H1: Emp ID | I1: A/C Title name | J1: Amount | K1: Internal/Engine
A2: 1 | B2: Itechnologi Tracking Services (PVT.) Ltd | C2: DIB | D2: 32705879 | E2: 45864 | F2: 45864 | G2: Chq 32705879 to Muhammad Umer Azeem against 100 Count Summary FMO Jun-2025 | H2: 10030 | I2: Muhammad Umer Azeem | J2: 7384
A3: 2 | B3: Itechnologi Tracking Services (PVT.) Ltd | C3: DIB | D3: 32705880 | E3: 45864 | F3: 45864 | G3: Chq 32705880 to Hannan Ali against 100 Count Summary FMO Jun-2025 | H3: 10391 | I3: Hannan Ali | J3: 7342
A4: 3 | B4: Itechnologi Tracking Services (PVT.) Ltd | C4: DIB | D4: 32705881 | E4: 45864 | F4: 45864 | G4: Chq 32705881 to Anil against 100 Count Summary FMO Jun-2025 | H4: 10019 | I4: Anil | J4: 5401
A5: 4 | B5: Itechnologi Tracking Services (PVT.) Ltd | C5: DIB | D5: 32705882 | E5: 45864 | F5: 45864 | G5: Chq 32705882 to Syed Sajid Hussain shah against 100 Count Summary FMO Jun-2025 | H5: 10290 | I5: Syed Sajid Hussain Shah | J5: 5063
A6: 5 | B6: Itechnologi Tracking Services (PVT.) Ltd | C6: DIB | D6: 32705883 | E6: 45864 | F6: 45864 | G6: Chq 32705883 to Muhammad Shahzad Aziz Bhatti against 100 Count Summary FMO Jun-2025 | H6: 10063 | I6: Muhammad Shahzad Aziz Bhatti | J6: 4810
A7: 6 | B7: Itechnologi Tracking Services (PVT.) Ltd | C7: DIB | D7: 32705721 | E7: 45864 | F7: 45864 | G7: Paid Cheque# 32705721 to Samuel Nawab (ID 10328) against Supervisor of the Month for the month of june 2025 | H7: 10328 | I7: Samuel Nawab | J7: 5000
A8: 7 | B8: Itechnologi Tracking Services (PVT.) Ltd | C8: DIB | D8: 32705764 | E8: 45864 | F8: 45864 | G8: Paid Cheque# 32705764 to Uzair Ahmed Ansari (ID 10554) against CRO 1st Employee Incentive for the month of june 2025 | H8: 10554 | I8: Uzair Ahmed Ansari | J8: 5000
A9: 8 | B9: Itechnologi Tracking Services (PVT.) Ltd | C9: DIB | D9: 32705765 | E9: 45864 | F9: 45864 | G9: Paid Cheque# 32705765 to Dawood Bose (ID 10533) against CRO 2nd Employee Incentive for the month of june 2025 | H9: 10533 | I9: Dawood Bose | J9: 4000
A10: 9 | B10: Itechnologi Tracking Services (PVT.) Ltd | C10: DIB | D10: 32705766 | E10: 45864 | F10: 45864 | G10: Paid Cheque# 32705766 to Alister (ID 10135) against CRO 3rd Employee Incentive for the month of june 2025 | H10: 10135 | I10: Alister Goden Gilbert | J10: 3000
A11: 10 | B11: Itechnologi Tracking Services (PVT.) Ltd | C11: DIB | D11: 32705767 | E11: 45864 | F11: 45864 | G11: Paid Cheque# 32705767 to Syed Ayyan Ali (ID 10239) against CRO Employee Incentive for the month of june 2025 | H11: 10239 | I11: Syed Ayyan Ali | J11: 2000
A12: 11 | B12: Itechnologi Tracking Services (PVT.) Ltd | C12: DIB | D12: 32705768 | E12: 45864 | F12: 45864 | G12: Paid Cheque# 32705768 to Awaiz Javed (ID 10430) against CRO Employee Incentive for the month of April 2025 | H12: 10430 | I12: Awaiz Javed | J12: 1000
A13: 15 | B13: Itechnologi Tracking Services (PVT.) Ltd | C13: DIB | D13: 32705855 | E13: 45864 | F13: 45864 | G13: Chq # 32705855 to Anil (ID 10019) against CR AM Commission FMO May,2025 | H13: 10019 | I13: Anil | J13: 86490
... A41: 43 | B41: Itechnologi Tracking Services (PVT.) Ltd | C41: DIB | D41: 32705732 | E41: 45864 | F41: 45864 | G41: Chq 32705732 to Muhammad Umer Azeem E # 9148 INT COM | H41: 10030 | I41: Muhammad Umer Azeem | J41: 250
A42: 44 | B42: Itechnologi Tracking Services (PVT.) Ltd | C42: DIB | D42: 32705733 | E42: 45864 | F42: 45864 | G42: Chq 32705733 to Muhammad Farhan (ID 10274) E # 249005 INT COM | H42: 10274 | I42: Muhammad Farhan | J42: 2000 | K42: E # 249005 INT COM
A43: 45 | B43: Itechnologi Tracking Services (PVT.) Ltd | C43: DIB | D43: 32705734 | E43: 45864 | F43: 45864 | G43: Chq 32705734 to Syed Amin Uddin Chishty E # 6R353495, G4NAMH303705 INT COM | H43: 10569 | I43: Syed Amin Uddin Chishty | J43: 2500 | K43: E # 6R353495, G4NAMH303705 INT COM
A44: 46 | B44: Itechnologi Tracking Services (PVT.) Ltd | C44: DIB | D44: 32705735 | E44: 45864 | F44: 45864 | G44: Chq 32705735 to Farhana Faisal E # Q374135(A) INT COM | H44: 10034 | I44: Farhana faisal | J44: 2750 | K44: E # Q374135(A) INT COM
A45: 47 | B45: Itechnologi Tracking Services (PVT.) Ltd | C45: DIB | D45: 32705736 | E45: 45864 | F45: 45864 | G45: Chq 32705736 to Muhammad Saif Malik E # G4NANU677475 INT COM | H45: 10431 | I45: Muhammad Saif Malik | J45: 2750 | K45: E # G4NANU677475 INT COM
A46: 49 | B46: Itechnologi Tracking Services (PVT.) Ltd | C46: DIB | D46: 32705774 | E46: 45864 | F46: 45864 | G46: Chq 32705774 to Farhana Faisal E # R06D-K192197, K0565801K, 1GD1571617 INT COM | H46: 10034 | I46: Farhana faisal | J46: 750 | K46: E # R06D-K192197, K0565801K, 1GD1571617 INT COM
A47: 50 | B47: Itechnologi Tracking Services (PVT.) Ltd | C47: DIB | D47: 32705776 | E47: 45864 | F47: 45864 | G47: Chq 32705776 to Syed Muhammad Hasnain E # 6R182632 INT COM | H47: 10163 | I47: Syed Muhammad Hasnain | J47: 750 | K47: E # 6R182632 INT COM
A48: 51 | B48: Itechnologi Tracking Services (PVT.) Ltd | C48: DIB | D48: 32705777 | E48: 45864 | F48: 45864 | G48: Chq 32705777 to Mohammad Yousuf E # G3LALP044593 INT COM | H48: 10407 | I48: Muhammad Yousuf | J48: 1250 | K48: E # G3LALP044593 INT COM
A49: 52 | B49: Itechnologi Tracking Services (PVT.) Ltd | C49: DIB | D49: 32705778 | E49: 45864 | F49: 45864 | G49: Chq 32705778 to Farhana Faisal E # PK10B122688 INT COM | H49: 10034 | I49: Farhana faisal | J49: 750 | K49: E # PK10B122688 INT COM
A50: 53 | B50: Itechnologi Tracking Services (PVT.) Ltd | C50: DIB | D50: 32705779 | E50: 45864 | F50: 45864 | G50: Chq 32705779 to Rahat Gul E # 2A19154 INT COM | H50: 10021 | I50: Rahat Gul | J50: 1250 | K50: # 2A19154 INT COM
A51: 54 | B51: Itechnologi Tracking Services (PVT.) Ltd | C51: DIB | D51: 32705896 | E51: 45864 | F51: 45864 | G51: Chq 32705896 to Mohammad Yousuf E # 2KDU570312 INT COM | H51: 10407 | I51: Muhammad Yousuf | J51: 1250 | K51: # 2KDU570312 INT COM
A52: 55 | B52: Itechnologi Tracking Services (PVT.) Ltd | C52: DIB | D52: 32705897 | E52: 45864 | F52: 45864 | G52: Chq 32705897 to Farhana Faisal E # R060D-K148188, KF-G521073, Q032803 INT COM | H52: 10034 | I52: Farhana faisal | J52: 750 | K52: E # R060D-K148188, KF-G521073, Q032803 INT COM
A53: 56 | B53: Itechnologi Tracking Services (PVT.) Ltd | C53: DIB | D53: 32705898 | E53: 45864 | F53: 45864 | G53: Chq 32705898 to Syed Muhammad Hasnain E # 6R249663 INT COM | H53: 10163 | I53: Syed Muhammad Hasnain | J53: 750 | K53: E # 6R249663 INT COM
A54: 57 | B54: Itechnologi Tracking Services (PVT.) Ltd | C54: DIB | D54: 32705688 | E54: 45864 | F54: 45864 | G54: Chq 32705688 to Muhammad Umer Azeem E # G4NLRH068879 INT COM | H54: 10030 | I54: Muhammad Umer Azeem | J54: 1250 | K54: E # G4NLRH068879 INT COM
A55: 58 | B55: Itechnologi Tracking Services (PVT.) Ltd | C55: DIB | D55: 32705686 | E55: 45864 | F55: 45864 | G55: Chq 32705686 to Babar Ali E # 1GD0632256 INT COM | H55: 10294 | I55: Babar Ali | J55: 1250 | K55: E # 1GD0632256 INT COM
A56: 59 | B56: Itechnologi Tracking Services (PVT.) Ltd | C56: DIB | D56: 32705687 | E56: 45864 | F56: 45864 | G56: Chq 32705687 to Syed Muhammad Hasnain E # 10TMA90006187,6R314029 INT COM | H56: 10163 | I56: Syed Muhammad Hasnain | J56: 4500 | K56: E # 10TMA90006187,6R314029 INT COM

Sheet Comission Aug 2025
A1: S.No | B1: Drawer Name | C1: Bank | D1: Cheque No. | E1: Receiving Month | F1: Finance Date | G1: Detail | H1: Emp ID | I1: A/C Title name | J1: Amount | K1: Internal/Engine
A2: 1 | B2: Itechnologi Tracking Services (PVT.) Ltd | C2: DIB | D2: 32882425 | E2: 45884 | F2: 45891 | G2: Muhammad Shakir Ghanchi (CRO Incentive) | H2: 10020 | I2: Muhammad Shakir Ghanchi | J2: 5000
A3: 2 | B3: Itechnologi Tracking Services (PVT.) Ltd | C3: DIB | D3: 32882426 | E3: 45884 | F3: 45891 | G3: Alishba Naveed (CRO Incentive) | H3: 10512 | I3: Alishba Naveed | J3: 5000
A4: 3 | B4: Itechnologi Tracking Services (PVT.) Ltd | C4: DIB | D4: 32882427 | E4: 45884 | F4: 45891 | G4: Alister Goden Gilbert (CRO Incentive) | H4: 10135 | I4: Alister Goden Gilbert | J4: 4000
A5: 4 | B5: Itechnologi Tracking Services (PVT.) Ltd | C5: DIB | D5: 32882428 | E5: 45884 | F5: 45891 | G5: Dawood Bose (CRO Incentive) | H5: 10494 | I5: Dawood Bose | J5: 3000
A6: 5 | B6: Itechnologi Tracking Services (PVT.) Ltd | C6: DIB | D6: 32882429 | E6: 45884 | F6: 45891 | G6: Uzair Ahmed Ansari (CRO Incentive) | H6: 10554 | I6: Uzair Ahmed Ansari | J6: 2000
A7: 6 | B7: Itechnologi Tracking Services (PVT.) Ltd | C7: DIB | D7: 32882430 | E7: 45884 | F7: 45891 | G7: Yashdial (CRO Incentive) | H7: 10437 | I7: Yashdial | J7: 1000
